[2025-05-14T12:18:19.320+0000] {processor.py:186} INFO - Started process (PID=184) to work on /opt/airflow/dags/yellowtripdata_dag.py
[2025-05-14T12:18:19.321+0000] {processor.py:914} INFO - Processing file /opt/airflow/dags/yellowtripdata_dag.py for tasks to queue
[2025-05-14T12:18:19.336+0000] {logging_mixin.py:190} INFO - [2025-05-14T12:18:19.335+0000] {dagbag.py:588} INFO - Filling up the DagBag from /opt/airflow/dags/yellowtripdata_dag.py
[2025-05-14T12:18:19.478+0000] {logging_mixin.py:190} INFO - [2025-05-14T12:18:19.377+0000] {dagbag.py:387} ERROR - Failed to import: /opt/airflow/dags/yellowtripdata_dag.py
Traceback (most recent call last):
  File "/home/airflow/.local/lib/python3.12/site-packages/airflow/models/dagbag.py", line 383, in parse
    loader.exec_module(new_module)
  File "<frozen importlib._bootstrap_external>", line 999, in exec_module
  File "<frozen importlib._bootstrap>", line 488, in _call_with_frames_removed
  File "/opt/airflow/dags/yellowtripdata_dag.py", line 41, in <module>
    yellowtripdata_dag()
  File "/home/airflow/.local/lib/python3.12/site-packages/airflow/models/dag.py", line 4307, in factory
    f(**f_kwargs)
  File "/opt/airflow/dags/yellowtripdata_dag.py", line 30, in yellowtripdata_dag
    yellowtripdata_analytics = DbtTaskGroup(
                               ^^^^^^^^^^^^^
  File "/home/airflow/.local/lib/python3.12/site-packages/cosmos/airflow/task_group.py", line 28, in __init__
    DbtToAirflowConverter.__init__(self, *args, **specific_kwargs(**kwargs))
  File "/home/airflow/.local/lib/python3.12/site-packages/cosmos/converter.py", line 256, in __init__
    project_config.validate_project()
  File "/home/airflow/.local/lib/python3.12/site-packages/cosmos/config.py", line 263, in validate_project
    raise CosmosValueError(f"Could not find {name} at {path}")
cosmos.exceptions.CosmosValueError: Could not find dbt_project.yml at /opt/airflow/dbt/dev/dbt_project.yml
[2025-05-14T12:18:19.479+0000] {processor.py:927} WARNING - No viable dags retrieved from /opt/airflow/dags/yellowtripdata_dag.py
[2025-05-14T12:18:19.965+0000] {processor.py:208} INFO - Processing /opt/airflow/dags/yellowtripdata_dag.py took 0.652 seconds
[2025-05-14T12:18:51.084+0000] {processor.py:186} INFO - Started process (PID=195) to work on /opt/airflow/dags/yellowtripdata_dag.py
[2025-05-14T12:18:51.088+0000] {processor.py:914} INFO - Processing file /opt/airflow/dags/yellowtripdata_dag.py for tasks to queue
[2025-05-14T12:18:51.099+0000] {logging_mixin.py:190} INFO - [2025-05-14T12:18:51.098+0000] {dagbag.py:588} INFO - Filling up the DagBag from /opt/airflow/dags/yellowtripdata_dag.py
[2025-05-14T12:18:51.143+0000] {logging_mixin.py:190} INFO - [2025-05-14T12:18:51.136+0000] {dagbag.py:387} ERROR - Failed to import: /opt/airflow/dags/yellowtripdata_dag.py
Traceback (most recent call last):
  File "/home/airflow/.local/lib/python3.12/site-packages/airflow/models/dagbag.py", line 383, in parse
    loader.exec_module(new_module)
  File "<frozen importlib._bootstrap_external>", line 999, in exec_module
  File "<frozen importlib._bootstrap>", line 488, in _call_with_frames_removed
  File "/opt/airflow/dags/yellowtripdata_dag.py", line 41, in <module>
    yellowtripdata_dag()
  File "/home/airflow/.local/lib/python3.12/site-packages/airflow/models/dag.py", line 4307, in factory
    f(**f_kwargs)
  File "/opt/airflow/dags/yellowtripdata_dag.py", line 30, in yellowtripdata_dag
    yellowtripdata_analytics = DbtTaskGroup(
                               ^^^^^^^^^^^^^
  File "/home/airflow/.local/lib/python3.12/site-packages/cosmos/airflow/task_group.py", line 28, in __init__
    DbtToAirflowConverter.__init__(self, *args, **specific_kwargs(**kwargs))
  File "/home/airflow/.local/lib/python3.12/site-packages/cosmos/converter.py", line 256, in __init__
    project_config.validate_project()
  File "/home/airflow/.local/lib/python3.12/site-packages/cosmos/config.py", line 263, in validate_project
    raise CosmosValueError(f"Could not find {name} at {path}")
cosmos.exceptions.CosmosValueError: Could not find dbt_project.yml at /opt/airflow/dbt/dev/dbt_project.yml
[2025-05-14T12:18:51.144+0000] {processor.py:927} WARNING - No viable dags retrieved from /opt/airflow/dags/yellowtripdata_dag.py
[2025-05-14T12:18:51.224+0000] {processor.py:208} INFO - Processing /opt/airflow/dags/yellowtripdata_dag.py took 0.163 seconds
[2025-05-14T12:19:22.165+0000] {processor.py:186} INFO - Started process (PID=207) to work on /opt/airflow/dags/yellowtripdata_dag.py
[2025-05-14T12:19:22.166+0000] {processor.py:914} INFO - Processing file /opt/airflow/dags/yellowtripdata_dag.py for tasks to queue
[2025-05-14T12:19:22.169+0000] {logging_mixin.py:190} INFO - [2025-05-14T12:19:22.168+0000] {dagbag.py:588} INFO - Filling up the DagBag from /opt/airflow/dags/yellowtripdata_dag.py
[2025-05-14T12:19:22.182+0000] {logging_mixin.py:190} INFO - [2025-05-14T12:19:22.179+0000] {dagbag.py:387} ERROR - Failed to import: /opt/airflow/dags/yellowtripdata_dag.py
Traceback (most recent call last):
  File "/home/airflow/.local/lib/python3.12/site-packages/airflow/models/dagbag.py", line 383, in parse
    loader.exec_module(new_module)
  File "<frozen importlib._bootstrap_external>", line 999, in exec_module
  File "<frozen importlib._bootstrap>", line 488, in _call_with_frames_removed
  File "/opt/airflow/dags/yellowtripdata_dag.py", line 41, in <module>
    yellowtripdata_dag()
  File "/home/airflow/.local/lib/python3.12/site-packages/airflow/models/dag.py", line 4307, in factory
    f(**f_kwargs)
  File "/opt/airflow/dags/yellowtripdata_dag.py", line 30, in yellowtripdata_dag
    yellowtripdata_analytics = DbtTaskGroup(
                               ^^^^^^^^^^^^^
  File "/home/airflow/.local/lib/python3.12/site-packages/cosmos/airflow/task_group.py", line 28, in __init__
    DbtToAirflowConverter.__init__(self, *args, **specific_kwargs(**kwargs))
  File "/home/airflow/.local/lib/python3.12/site-packages/cosmos/converter.py", line 256, in __init__
    project_config.validate_project()
  File "/home/airflow/.local/lib/python3.12/site-packages/cosmos/config.py", line 263, in validate_project
    raise CosmosValueError(f"Could not find {name} at {path}")
cosmos.exceptions.CosmosValueError: Could not find dbt_project.yml at /opt/airflow/dbt/dev/dbt_project.yml
[2025-05-14T12:19:22.182+0000] {processor.py:927} WARNING - No viable dags retrieved from /opt/airflow/dags/yellowtripdata_dag.py
[2025-05-14T12:19:22.268+0000] {processor.py:208} INFO - Processing /opt/airflow/dags/yellowtripdata_dag.py took 0.110 seconds
[2025-05-14T12:19:53.117+0000] {processor.py:186} INFO - Started process (PID=218) to work on /opt/airflow/dags/yellowtripdata_dag.py
[2025-05-14T12:19:53.118+0000] {processor.py:914} INFO - Processing file /opt/airflow/dags/yellowtripdata_dag.py for tasks to queue
[2025-05-14T12:19:53.121+0000] {logging_mixin.py:190} INFO - [2025-05-14T12:19:53.121+0000] {dagbag.py:588} INFO - Filling up the DagBag from /opt/airflow/dags/yellowtripdata_dag.py
[2025-05-14T12:19:53.142+0000] {logging_mixin.py:190} INFO - [2025-05-14T12:19:53.132+0000] {dagbag.py:387} ERROR - Failed to import: /opt/airflow/dags/yellowtripdata_dag.py
Traceback (most recent call last):
  File "/home/airflow/.local/lib/python3.12/site-packages/airflow/models/dagbag.py", line 383, in parse
    loader.exec_module(new_module)
  File "<frozen importlib._bootstrap_external>", line 999, in exec_module
  File "<frozen importlib._bootstrap>", line 488, in _call_with_frames_removed
  File "/opt/airflow/dags/yellowtripdata_dag.py", line 41, in <module>
    yellowtripdata_dag()
  File "/home/airflow/.local/lib/python3.12/site-packages/airflow/models/dag.py", line 4307, in factory
    f(**f_kwargs)
  File "/opt/airflow/dags/yellowtripdata_dag.py", line 30, in yellowtripdata_dag
    yellowtripdata_analytics = DbtTaskGroup(
                               ^^^^^^^^^^^^^
  File "/home/airflow/.local/lib/python3.12/site-packages/cosmos/airflow/task_group.py", line 28, in __init__
    DbtToAirflowConverter.__init__(self, *args, **specific_kwargs(**kwargs))
  File "/home/airflow/.local/lib/python3.12/site-packages/cosmos/converter.py", line 256, in __init__
    project_config.validate_project()
  File "/home/airflow/.local/lib/python3.12/site-packages/cosmos/config.py", line 263, in validate_project
    raise CosmosValueError(f"Could not find {name} at {path}")
cosmos.exceptions.CosmosValueError: Could not find dbt_project.yml at /opt/airflow/dbt/dev/dbt_project.yml
[2025-05-14T12:19:53.145+0000] {processor.py:927} WARNING - No viable dags retrieved from /opt/airflow/dags/yellowtripdata_dag.py
[2025-05-14T12:19:53.188+0000] {processor.py:208} INFO - Processing /opt/airflow/dags/yellowtripdata_dag.py took 0.079 seconds
[2025-05-14T12:20:24.199+0000] {processor.py:186} INFO - Started process (PID=229) to work on /opt/airflow/dags/yellowtripdata_dag.py
[2025-05-14T12:20:24.201+0000] {processor.py:914} INFO - Processing file /opt/airflow/dags/yellowtripdata_dag.py for tasks to queue
[2025-05-14T12:20:24.204+0000] {logging_mixin.py:190} INFO - [2025-05-14T12:20:24.204+0000] {dagbag.py:588} INFO - Filling up the DagBag from /opt/airflow/dags/yellowtripdata_dag.py
[2025-05-14T12:20:24.222+0000] {logging_mixin.py:190} INFO - [2025-05-14T12:20:24.218+0000] {dagbag.py:387} ERROR - Failed to import: /opt/airflow/dags/yellowtripdata_dag.py
Traceback (most recent call last):
  File "/home/airflow/.local/lib/python3.12/site-packages/airflow/models/dagbag.py", line 383, in parse
    loader.exec_module(new_module)
  File "<frozen importlib._bootstrap_external>", line 999, in exec_module
  File "<frozen importlib._bootstrap>", line 488, in _call_with_frames_removed
  File "/opt/airflow/dags/yellowtripdata_dag.py", line 41, in <module>
    yellowtripdata_dag()
  File "/home/airflow/.local/lib/python3.12/site-packages/airflow/models/dag.py", line 4307, in factory
    f(**f_kwargs)
  File "/opt/airflow/dags/yellowtripdata_dag.py", line 30, in yellowtripdata_dag
    yellowtripdata_analytics = DbtTaskGroup(
                               ^^^^^^^^^^^^^
  File "/home/airflow/.local/lib/python3.12/site-packages/cosmos/airflow/task_group.py", line 28, in __init__
    DbtToAirflowConverter.__init__(self, *args, **specific_kwargs(**kwargs))
  File "/home/airflow/.local/lib/python3.12/site-packages/cosmos/converter.py", line 256, in __init__
    project_config.validate_project()
  File "/home/airflow/.local/lib/python3.12/site-packages/cosmos/config.py", line 263, in validate_project
    raise CosmosValueError(f"Could not find {name} at {path}")
cosmos.exceptions.CosmosValueError: Could not find dbt_project.yml at /opt/airflow/dbt/dev/dbt_project.yml
[2025-05-14T12:20:24.224+0000] {processor.py:927} WARNING - No viable dags retrieved from /opt/airflow/dags/yellowtripdata_dag.py
[2025-05-14T12:20:24.265+0000] {processor.py:208} INFO - Processing /opt/airflow/dags/yellowtripdata_dag.py took 0.075 seconds
[2025-05-14T12:20:55.196+0000] {processor.py:186} INFO - Started process (PID=240) to work on /opt/airflow/dags/yellowtripdata_dag.py
[2025-05-14T12:20:55.198+0000] {processor.py:914} INFO - Processing file /opt/airflow/dags/yellowtripdata_dag.py for tasks to queue
[2025-05-14T12:20:55.201+0000] {logging_mixin.py:190} INFO - [2025-05-14T12:20:55.201+0000] {dagbag.py:588} INFO - Filling up the DagBag from /opt/airflow/dags/yellowtripdata_dag.py
[2025-05-14T12:20:55.219+0000] {logging_mixin.py:190} INFO - [2025-05-14T12:20:55.215+0000] {dagbag.py:387} ERROR - Failed to import: /opt/airflow/dags/yellowtripdata_dag.py
Traceback (most recent call last):
  File "/home/airflow/.local/lib/python3.12/site-packages/airflow/models/dagbag.py", line 383, in parse
    loader.exec_module(new_module)
  File "<frozen importlib._bootstrap_external>", line 999, in exec_module
  File "<frozen importlib._bootstrap>", line 488, in _call_with_frames_removed
  File "/opt/airflow/dags/yellowtripdata_dag.py", line 41, in <module>
    yellowtripdata_dag()
  File "/home/airflow/.local/lib/python3.12/site-packages/airflow/models/dag.py", line 4307, in factory
    f(**f_kwargs)
  File "/opt/airflow/dags/yellowtripdata_dag.py", line 30, in yellowtripdata_dag
    yellowtripdata_analytics = DbtTaskGroup(
                               ^^^^^^^^^^^^^
  File "/home/airflow/.local/lib/python3.12/site-packages/cosmos/airflow/task_group.py", line 28, in __init__
    DbtToAirflowConverter.__init__(self, *args, **specific_kwargs(**kwargs))
  File "/home/airflow/.local/lib/python3.12/site-packages/cosmos/converter.py", line 256, in __init__
    project_config.validate_project()
  File "/home/airflow/.local/lib/python3.12/site-packages/cosmos/config.py", line 263, in validate_project
    raise CosmosValueError(f"Could not find {name} at {path}")
cosmos.exceptions.CosmosValueError: Could not find dbt_project.yml at /opt/airflow/dbt/dev/dbt_project.yml
[2025-05-14T12:20:55.220+0000] {processor.py:927} WARNING - No viable dags retrieved from /opt/airflow/dags/yellowtripdata_dag.py
[2025-05-14T12:20:55.278+0000] {processor.py:208} INFO - Processing /opt/airflow/dags/yellowtripdata_dag.py took 0.092 seconds
[2025-05-14T12:21:27.067+0000] {processor.py:186} INFO - Started process (PID=251) to work on /opt/airflow/dags/yellowtripdata_dag.py
[2025-05-14T12:21:27.069+0000] {processor.py:914} INFO - Processing file /opt/airflow/dags/yellowtripdata_dag.py for tasks to queue
[2025-05-14T12:21:27.072+0000] {logging_mixin.py:190} INFO - [2025-05-14T12:21:27.071+0000] {dagbag.py:588} INFO - Filling up the DagBag from /opt/airflow/dags/yellowtripdata_dag.py
[2025-05-14T12:21:27.105+0000] {logging_mixin.py:190} INFO - [2025-05-14T12:21:27.099+0000] {dagbag.py:387} ERROR - Failed to import: /opt/airflow/dags/yellowtripdata_dag.py
Traceback (most recent call last):
  File "/home/airflow/.local/lib/python3.12/site-packages/airflow/models/dagbag.py", line 383, in parse
    loader.exec_module(new_module)
  File "<frozen importlib._bootstrap_external>", line 999, in exec_module
  File "<frozen importlib._bootstrap>", line 488, in _call_with_frames_removed
  File "/opt/airflow/dags/yellowtripdata_dag.py", line 41, in <module>
    yellowtripdata_dag()
  File "/home/airflow/.local/lib/python3.12/site-packages/airflow/models/dag.py", line 4307, in factory
    f(**f_kwargs)
  File "/opt/airflow/dags/yellowtripdata_dag.py", line 30, in yellowtripdata_dag
    yellowtripdata_analytics = DbtTaskGroup(
                               ^^^^^^^^^^^^^
  File "/home/airflow/.local/lib/python3.12/site-packages/cosmos/airflow/task_group.py", line 28, in __init__
    DbtToAirflowConverter.__init__(self, *args, **specific_kwargs(**kwargs))
  File "/home/airflow/.local/lib/python3.12/site-packages/cosmos/converter.py", line 256, in __init__
    project_config.validate_project()
  File "/home/airflow/.local/lib/python3.12/site-packages/cosmos/config.py", line 263, in validate_project
    raise CosmosValueError(f"Could not find {name} at {path}")
cosmos.exceptions.CosmosValueError: Could not find dbt_project.yml at /opt/airflow/dbt/dev/dbt_project.yml
[2025-05-14T12:21:27.106+0000] {processor.py:927} WARNING - No viable dags retrieved from /opt/airflow/dags/yellowtripdata_dag.py
[2025-05-14T12:21:27.145+0000] {processor.py:208} INFO - Processing /opt/airflow/dags/yellowtripdata_dag.py took 0.085 seconds
[2025-05-14T12:21:58.178+0000] {processor.py:186} INFO - Started process (PID=262) to work on /opt/airflow/dags/yellowtripdata_dag.py
[2025-05-14T12:21:58.234+0000] {processor.py:914} INFO - Processing file /opt/airflow/dags/yellowtripdata_dag.py for tasks to queue
[2025-05-14T12:21:58.237+0000] {logging_mixin.py:190} INFO - [2025-05-14T12:21:58.236+0000] {dagbag.py:588} INFO - Filling up the DagBag from /opt/airflow/dags/yellowtripdata_dag.py
[2025-05-14T12:21:58.260+0000] {logging_mixin.py:190} INFO - [2025-05-14T12:21:58.247+0000] {dagbag.py:387} ERROR - Failed to import: /opt/airflow/dags/yellowtripdata_dag.py
Traceback (most recent call last):
  File "/home/airflow/.local/lib/python3.12/site-packages/airflow/models/dagbag.py", line 383, in parse
    loader.exec_module(new_module)
  File "<frozen importlib._bootstrap_external>", line 999, in exec_module
  File "<frozen importlib._bootstrap>", line 488, in _call_with_frames_removed
  File "/opt/airflow/dags/yellowtripdata_dag.py", line 41, in <module>
    yellowtripdata_dag()
  File "/home/airflow/.local/lib/python3.12/site-packages/airflow/models/dag.py", line 4307, in factory
    f(**f_kwargs)
  File "/opt/airflow/dags/yellowtripdata_dag.py", line 30, in yellowtripdata_dag
    yellowtripdata_analytics = DbtTaskGroup(
                               ^^^^^^^^^^^^^
  File "/home/airflow/.local/lib/python3.12/site-packages/cosmos/airflow/task_group.py", line 28, in __init__
    DbtToAirflowConverter.__init__(self, *args, **specific_kwargs(**kwargs))
  File "/home/airflow/.local/lib/python3.12/site-packages/cosmos/converter.py", line 256, in __init__
    project_config.validate_project()
  File "/home/airflow/.local/lib/python3.12/site-packages/cosmos/config.py", line 263, in validate_project
    raise CosmosValueError(f"Could not find {name} at {path}")
cosmos.exceptions.CosmosValueError: Could not find dbt_project.yml at /opt/airflow/dbt/dev/dbt_project.yml
[2025-05-14T12:21:58.260+0000] {processor.py:927} WARNING - No viable dags retrieved from /opt/airflow/dags/yellowtripdata_dag.py
[2025-05-14T12:21:58.293+0000] {processor.py:208} INFO - Processing /opt/airflow/dags/yellowtripdata_dag.py took 0.122 seconds
[2025-05-14T12:22:28.763+0000] {processor.py:186} INFO - Started process (PID=273) to work on /opt/airflow/dags/yellowtripdata_dag.py
[2025-05-14T12:22:28.765+0000] {processor.py:914} INFO - Processing file /opt/airflow/dags/yellowtripdata_dag.py for tasks to queue
[2025-05-14T12:22:28.767+0000] {logging_mixin.py:190} INFO - [2025-05-14T12:22:28.767+0000] {dagbag.py:588} INFO - Filling up the DagBag from /opt/airflow/dags/yellowtripdata_dag.py
[2025-05-14T12:22:28.780+0000] {logging_mixin.py:190} INFO - [2025-05-14T12:22:28.777+0000] {dagbag.py:387} ERROR - Failed to import: /opt/airflow/dags/yellowtripdata_dag.py
Traceback (most recent call last):
  File "/home/airflow/.local/lib/python3.12/site-packages/airflow/models/dagbag.py", line 383, in parse
    loader.exec_module(new_module)
  File "<frozen importlib._bootstrap_external>", line 999, in exec_module
  File "<frozen importlib._bootstrap>", line 488, in _call_with_frames_removed
  File "/opt/airflow/dags/yellowtripdata_dag.py", line 41, in <module>
    yellowtripdata_dag()
  File "/home/airflow/.local/lib/python3.12/site-packages/airflow/models/dag.py", line 4307, in factory
    f(**f_kwargs)
  File "/opt/airflow/dags/yellowtripdata_dag.py", line 30, in yellowtripdata_dag
    yellowtripdata_analytics = DbtTaskGroup(
                               ^^^^^^^^^^^^^
  File "/home/airflow/.local/lib/python3.12/site-packages/cosmos/airflow/task_group.py", line 28, in __init__
    DbtToAirflowConverter.__init__(self, *args, **specific_kwargs(**kwargs))
  File "/home/airflow/.local/lib/python3.12/site-packages/cosmos/converter.py", line 256, in __init__
    project_config.validate_project()
  File "/home/airflow/.local/lib/python3.12/site-packages/cosmos/config.py", line 263, in validate_project
    raise CosmosValueError(f"Could not find {name} at {path}")
cosmos.exceptions.CosmosValueError: Could not find dbt_project.yml at /opt/airflow/dbt/dev/dbt_project.yml
[2025-05-14T12:22:28.780+0000] {processor.py:927} WARNING - No viable dags retrieved from /opt/airflow/dags/yellowtripdata_dag.py
[2025-05-14T12:22:28.909+0000] {processor.py:208} INFO - Processing /opt/airflow/dags/yellowtripdata_dag.py took 0.157 seconds
[2025-05-14T15:08:27.504+0000] {processor.py:186} INFO - Started process (PID=191) to work on /opt/airflow/dags/yellowtripdata_dag.py
[2025-05-14T15:08:27.508+0000] {processor.py:914} INFO - Processing file /opt/airflow/dags/yellowtripdata_dag.py for tasks to queue
[2025-05-14T15:08:27.515+0000] {logging_mixin.py:190} INFO - [2025-05-14T15:08:27.513+0000] {dagbag.py:588} INFO - Filling up the DagBag from /opt/airflow/dags/yellowtripdata_dag.py
[2025-05-14T15:08:28.182+0000] {logging_mixin.py:190} INFO - [2025-05-14T15:08:28.159+0000] {dagbag.py:387} ERROR - Failed to import: /opt/airflow/dags/yellowtripdata_dag.py
Traceback (most recent call last):
  File "/home/airflow/.local/lib/python3.12/site-packages/airflow/models/dagbag.py", line 383, in parse
    loader.exec_module(new_module)
  File "<frozen importlib._bootstrap_external>", line 999, in exec_module
  File "<frozen importlib._bootstrap>", line 488, in _call_with_frames_removed
  File "/opt/airflow/dags/yellowtripdata_dag.py", line 41, in <module>
    yellowtripdata_dag()
  File "/home/airflow/.local/lib/python3.12/site-packages/airflow/models/dag.py", line 4307, in factory
    f(**f_kwargs)
  File "/opt/airflow/dags/yellowtripdata_dag.py", line 30, in yellowtripdata_dag
    yellowtripdata_analytics = DbtTaskGroup(
                               ^^^^^^^^^^^^^
  File "/home/airflow/.local/lib/python3.12/site-packages/cosmos/airflow/task_group.py", line 28, in __init__
    DbtToAirflowConverter.__init__(self, *args, **specific_kwargs(**kwargs))
  File "/home/airflow/.local/lib/python3.12/site-packages/cosmos/converter.py", line 256, in __init__
    project_config.validate_project()
  File "/home/airflow/.local/lib/python3.12/site-packages/cosmos/config.py", line 263, in validate_project
    raise CosmosValueError(f"Could not find {name} at {path}")
cosmos.exceptions.CosmosValueError: Could not find dbt_project.yml at /opt/airflow/dbt/dev/dbt_project.yml
[2025-05-14T15:08:28.183+0000] {processor.py:927} WARNING - No viable dags retrieved from /opt/airflow/dags/yellowtripdata_dag.py
[2025-05-14T15:08:28.238+0000] {processor.py:208} INFO - Processing /opt/airflow/dags/yellowtripdata_dag.py took 0.801 seconds
[2025-05-14T15:08:59.044+0000] {processor.py:186} INFO - Started process (PID=201) to work on /opt/airflow/dags/yellowtripdata_dag.py
[2025-05-14T15:08:59.050+0000] {processor.py:914} INFO - Processing file /opt/airflow/dags/yellowtripdata_dag.py for tasks to queue
[2025-05-14T15:08:59.058+0000] {logging_mixin.py:190} INFO - [2025-05-14T15:08:59.057+0000] {dagbag.py:588} INFO - Filling up the DagBag from /opt/airflow/dags/yellowtripdata_dag.py
[2025-05-14T15:08:59.097+0000] {logging_mixin.py:190} INFO - [2025-05-14T15:08:59.085+0000] {dagbag.py:387} ERROR - Failed to import: /opt/airflow/dags/yellowtripdata_dag.py
Traceback (most recent call last):
  File "/home/airflow/.local/lib/python3.12/site-packages/airflow/models/dagbag.py", line 383, in parse
    loader.exec_module(new_module)
  File "<frozen importlib._bootstrap_external>", line 999, in exec_module
  File "<frozen importlib._bootstrap>", line 488, in _call_with_frames_removed
  File "/opt/airflow/dags/yellowtripdata_dag.py", line 41, in <module>
    yellowtripdata_dag()
  File "/home/airflow/.local/lib/python3.12/site-packages/airflow/models/dag.py", line 4307, in factory
    f(**f_kwargs)
  File "/opt/airflow/dags/yellowtripdata_dag.py", line 30, in yellowtripdata_dag
    yellowtripdata_analytics = DbtTaskGroup(
                               ^^^^^^^^^^^^^
  File "/home/airflow/.local/lib/python3.12/site-packages/cosmos/airflow/task_group.py", line 28, in __init__
    DbtToAirflowConverter.__init__(self, *args, **specific_kwargs(**kwargs))
  File "/home/airflow/.local/lib/python3.12/site-packages/cosmos/converter.py", line 256, in __init__
    project_config.validate_project()
  File "/home/airflow/.local/lib/python3.12/site-packages/cosmos/config.py", line 263, in validate_project
    raise CosmosValueError(f"Could not find {name} at {path}")
cosmos.exceptions.CosmosValueError: Could not find dbt_project.yml at /opt/airflow/dbt/dev/dbt_project.yml
[2025-05-14T15:08:59.098+0000] {processor.py:927} WARNING - No viable dags retrieved from /opt/airflow/dags/yellowtripdata_dag.py
[2025-05-14T15:08:59.114+0000] {processor.py:211} ERROR - Got an exception! Propagating...
Traceback (most recent call last):
  File "/home/airflow/.local/lib/python3.12/site-packages/sqlalchemy/engine/base.py", line 3371, in _wrap_pool_connect
    return fn()
           ^^^^
  File "/home/airflow/.local/lib/python3.12/site-packages/sqlalchemy/pool/base.py", line 327, in connect
    return _ConnectionFairy._checkout(self)
           ^^^^^^^^^^^^^^^^^^^^^^^^^^^^^^^^
  File "/home/airflow/.local/lib/python3.12/site-packages/sqlalchemy/pool/base.py", line 894, in _checkout
    fairy = _ConnectionRecord.checkout(pool)
            ^^^^^^^^^^^^^^^^^^^^^^^^^^^^^^^^
  File "/home/airflow/.local/lib/python3.12/site-packages/sqlalchemy/pool/base.py", line 493, in checkout
    rec = pool._do_get()
          ^^^^^^^^^^^^^^
  File "/home/airflow/.local/lib/python3.12/site-packages/sqlalchemy/pool/impl.py", line 145, in _do_get
    with util.safe_reraise():
         ^^^^^^^^^^^^^^^^^^^
  File "/home/airflow/.local/lib/python3.12/site-packages/sqlalchemy/util/langhelpers.py", line 70, in __exit__
    compat.raise_(
  File "/home/airflow/.local/lib/python3.12/site-packages/sqlalchemy/util/compat.py", line 211, in raise_
    raise exception
  File "/home/airflow/.local/lib/python3.12/site-packages/sqlalchemy/pool/impl.py", line 143, in _do_get
    return self._create_connection()
           ^^^^^^^^^^^^^^^^^^^^^^^^^
  File "/home/airflow/.local/lib/python3.12/site-packages/sqlalchemy/pool/base.py", line 273, in _create_connection
    return _ConnectionRecord(self)
           ^^^^^^^^^^^^^^^^^^^^^^^
  File "/home/airflow/.local/lib/python3.12/site-packages/sqlalchemy/pool/base.py", line 388, in __init__
    self.__connect()
  File "/home/airflow/.local/lib/python3.12/site-packages/sqlalchemy/pool/base.py", line 690, in __connect
    with util.safe_reraise():
         ^^^^^^^^^^^^^^^^^^^
  File "/home/airflow/.local/lib/python3.12/site-packages/sqlalchemy/util/langhelpers.py", line 70, in __exit__
    compat.raise_(
  File "/home/airflow/.local/lib/python3.12/site-packages/sqlalchemy/util/compat.py", line 211, in raise_
    raise exception
  File "/home/airflow/.local/lib/python3.12/site-packages/sqlalchemy/pool/base.py", line 686, in __connect
    self.dbapi_connection = connection = pool._invoke_creator(self)
                                         ^^^^^^^^^^^^^^^^^^^^^^^^^^
  File "/home/airflow/.local/lib/python3.12/site-packages/sqlalchemy/engine/create.py", line 574, in connect
    return dialect.connect(*cargs, **cparams)
           ^^^^^^^^^^^^^^^^^^^^^^^^^^^^^^^^^^
  File "/home/airflow/.local/lib/python3.12/site-packages/sqlalchemy/engine/default.py", line 598, in connect
    return self.dbapi.connect(*cargs, **cparams)
           ^^^^^^^^^^^^^^^^^^^^^^^^^^^^^^^^^^^^^
  File "/home/airflow/.local/lib/python3.12/site-packages/psycopg2/__init__.py", line 122, in connect
    conn = _connect(dsn, connection_factory=connection_factory, **kwasync)
           ^^^^^^^^^^^^^^^^^^^^^^^^^^^^^^^^^^^^^^^^^^^^^^^^^^^^^^^^^^^^^^^
psycopg2.OperationalError: connection to server at "postgres" (172.22.0.2), port 5432 failed: FATAL:  the database system is shutting down


The above exception was the direct cause of the following exception:

Traceback (most recent call last):
  File "/home/airflow/.local/lib/python3.12/site-packages/airflow/dag_processing/processor.py", line 207, in _run_file_processor
    _handle_dag_file_processing()
  File "/home/airflow/.local/lib/python3.12/site-packages/airflow/dag_processing/processor.py", line 188, in _handle_dag_file_processing
    result: tuple[int, int, int] = dag_file_processor.process_file(
                                   ^^^^^^^^^^^^^^^^^^^^^^^^^^^^^^^^
  File "/home/airflow/.local/lib/python3.12/site-packages/airflow/utils/session.py", line 97, in wrapper
    return func(*args, session=session, **kwargs)
           ^^^^^^^^^^^^^^^^^^^^^^^^^^^^^^^^^^^^^^
  File "/home/airflow/.local/lib/python3.12/site-packages/airflow/dag_processing/processor.py", line 928, in process_file
    DagFileProcessor.update_import_errors(
  File "/home/airflow/.local/lib/python3.12/site-packages/airflow/api_internal/internal_api_call.py", line 166, in wrapper
    return func(*args, **kwargs)
           ^^^^^^^^^^^^^^^^^^^^^
  File "/home/airflow/.local/lib/python3.12/site-packages/airflow/utils/session.py", line 97, in wrapper
    return func(*args, session=session, **kwargs)
           ^^^^^^^^^^^^^^^^^^^^^^^^^^^^^^^^^^^^^^
  File "/home/airflow/.local/lib/python3.12/site-packages/airflow/dag_processing/processor.py", line 648, in update_import_errors
    existing_import_error_files = [x.filename for x in session.query(ParseImportError.filename).all()]
                                                       ^^^^^^^^^^^^^^^^^^^^^^^^^^^^^^^^^^^^^^^^^^^^^^
  File "/home/airflow/.local/lib/python3.12/site-packages/sqlalchemy/orm/query.py", line 2773, in all
    return self._iter().all()
           ^^^^^^^^^^^^
  File "/home/airflow/.local/lib/python3.12/site-packages/sqlalchemy/orm/query.py", line 2916, in _iter
    result = self.session.execute(
             ^^^^^^^^^^^^^^^^^^^^^
  File "/home/airflow/.local/lib/python3.12/site-packages/sqlalchemy/orm/session.py", line 1716, in execute
    conn = self._connection_for_bind(bind)
           ^^^^^^^^^^^^^^^^^^^^^^^^^^^^^^^
  File "/home/airflow/.local/lib/python3.12/site-packages/sqlalchemy/orm/session.py", line 1555, in _connection_for_bind
    return self._transaction._connection_for_bind(
           ^^^^^^^^^^^^^^^^^^^^^^^^^^^^^^^^^^^^^^^
  File "/home/airflow/.local/lib/python3.12/site-packages/sqlalchemy/orm/session.py", line 750, in _connection_for_bind
    conn = bind.connect()
           ^^^^^^^^^^^^^^
  File "/home/airflow/.local/lib/python3.12/site-packages/sqlalchemy/future/engine.py", line 412, in connect
    return super(Engine, self).connect()
           ^^^^^^^^^^^^^^^^^^^^^^^^^^^^^
  File "/home/airflow/.local/lib/python3.12/site-packages/sqlalchemy/engine/base.py", line 3325, in connect
    return self._connection_cls(self, close_with_result=close_with_result)
           ^^^^^^^^^^^^^^^^^^^^^^^^^^^^^^^^^^^^^^^^^^^^^^^^^^^^^^^^^^^^^^^
  File "/home/airflow/.local/lib/python3.12/site-packages/sqlalchemy/engine/base.py", line 96, in __init__
    else engine.raw_connection()
         ^^^^^^^^^^^^^^^^^^^^^^^
  File "/home/airflow/.local/lib/python3.12/site-packages/sqlalchemy/engine/base.py", line 3404, in raw_connection
    return self._wrap_pool_connect(self.pool.connect, _connection)
           ^^^^^^^^^^^^^^^^^^^^^^^^^^^^^^^^^^^^^^^^^^^^^^^^^^^^^^^
  File "/home/airflow/.local/lib/python3.12/site-packages/sqlalchemy/engine/base.py", line 3374, in _wrap_pool_connect
    Connection._handle_dbapi_exception_noconnection(
  File "/home/airflow/.local/lib/python3.12/site-packages/sqlalchemy/engine/base.py", line 2208, in _handle_dbapi_exception_noconnection
    util.raise_(
  File "/home/airflow/.local/lib/python3.12/site-packages/sqlalchemy/util/compat.py", line 211, in raise_
    raise exception
  File "/home/airflow/.local/lib/python3.12/site-packages/sqlalchemy/engine/base.py", line 3371, in _wrap_pool_connect
    return fn()
           ^^^^
  File "/home/airflow/.local/lib/python3.12/site-packages/sqlalchemy/pool/base.py", line 327, in connect
    return _ConnectionFairy._checkout(self)
           ^^^^^^^^^^^^^^^^^^^^^^^^^^^^^^^^
  File "/home/airflow/.local/lib/python3.12/site-packages/sqlalchemy/pool/base.py", line 894, in _checkout
    fairy = _ConnectionRecord.checkout(pool)
            ^^^^^^^^^^^^^^^^^^^^^^^^^^^^^^^^
  File "/home/airflow/.local/lib/python3.12/site-packages/sqlalchemy/pool/base.py", line 493, in checkout
    rec = pool._do_get()
          ^^^^^^^^^^^^^^
  File "/home/airflow/.local/lib/python3.12/site-packages/sqlalchemy/pool/impl.py", line 145, in _do_get
    with util.safe_reraise():
         ^^^^^^^^^^^^^^^^^^^
  File "/home/airflow/.local/lib/python3.12/site-packages/sqlalchemy/util/langhelpers.py", line 70, in __exit__
    compat.raise_(
  File "/home/airflow/.local/lib/python3.12/site-packages/sqlalchemy/util/compat.py", line 211, in raise_
    raise exception
  File "/home/airflow/.local/lib/python3.12/site-packages/sqlalchemy/pool/impl.py", line 143, in _do_get
    return self._create_connection()
           ^^^^^^^^^^^^^^^^^^^^^^^^^
  File "/home/airflow/.local/lib/python3.12/site-packages/sqlalchemy/pool/base.py", line 273, in _create_connection
    return _ConnectionRecord(self)
           ^^^^^^^^^^^^^^^^^^^^^^^
  File "/home/airflow/.local/lib/python3.12/site-packages/sqlalchemy/pool/base.py", line 388, in __init__
    self.__connect()
  File "/home/airflow/.local/lib/python3.12/site-packages/sqlalchemy/pool/base.py", line 690, in __connect
    with util.safe_reraise():
         ^^^^^^^^^^^^^^^^^^^
  File "/home/airflow/.local/lib/python3.12/site-packages/sqlalchemy/util/langhelpers.py", line 70, in __exit__
    compat.raise_(
  File "/home/airflow/.local/lib/python3.12/site-packages/sqlalchemy/util/compat.py", line 211, in raise_
    raise exception
  File "/home/airflow/.local/lib/python3.12/site-packages/sqlalchemy/pool/base.py", line 686, in __connect
    self.dbapi_connection = connection = pool._invoke_creator(self)
                                         ^^^^^^^^^^^^^^^^^^^^^^^^^^
  File "/home/airflow/.local/lib/python3.12/site-packages/sqlalchemy/engine/create.py", line 574, in connect
    return dialect.connect(*cargs, **cparams)
           ^^^^^^^^^^^^^^^^^^^^^^^^^^^^^^^^^^
  File "/home/airflow/.local/lib/python3.12/site-packages/sqlalchemy/engine/default.py", line 598, in connect
    return self.dbapi.connect(*cargs, **cparams)
           ^^^^^^^^^^^^^^^^^^^^^^^^^^^^^^^^^^^^^
  File "/home/airflow/.local/lib/python3.12/site-packages/psycopg2/__init__.py", line 122, in connect
    conn = _connect(dsn, connection_factory=connection_factory, **kwasync)
           ^^^^^^^^^^^^^^^^^^^^^^^^^^^^^^^^^^^^^^^^^^^^^^^^^^^^^^^^^^^^^^^
sqlalchemy.exc.OperationalError: (psycopg2.OperationalError) connection to server at "postgres" (172.22.0.2), port 5432 failed: FATAL:  the database system is shutting down

(Background on this error at: https://sqlalche.me/e/14/e3q8)
